<?xml version="1.0" encoding="utf-8"?>
<robot xmlns:xacro="http://www.ros.org/wiki/xacro" name="hand">
  <xacro:macro name="hand" params="connected_to:='' ns:='' rpy:='0 0 0' xyz:='0 0 0' ">
    <xacro:unless value="${connected_to == ''}">
      <joint name="${ns}_hand_joint" type="fixed">
        <parent link="${connected_to}"/>
        <child link="${ns}_hand"/>
        <origin xyz="${xyz}" rpy="${rpy}"/>
      </joint>
    </xacro:unless>

    <xacro:arg name="gazebo" default="true"/>
    <xacro:if value="$(arg gazebo)">
      <!-- Gazebo Tags -->
      <xacro:include filename="$(find franka_gazebo)/robots/hand.gazebo.xacro"/>
    </xacro:if>

    <link name="${ns}_hand">
      <inertial>
        <mass value="0.73" />
        <origin xyz="0 0.0015244 0.0275912" rpy="0 0 0" />
        <inertia ixx="0.00278560230025" ixy="0.0" ixz="0.0" iyy="0.000400033405336" iyz="0.0" izz="0.00256378041832" />
      </inertial>
      <visual>
        <origin xyz="${xyz}" rpy="0 0 0"/>
        <geometry>
          <mesh filename="package://franka_gazebo/meshes/visual/hand.dae"/>
        </geometry>
        <material name="">
          <color rgba="1 1 1 1"/>
        </material>
      </visual>
      <collision>
        <origin xyz="${xyz}" rpy="0 0 0"/>
        <geometry>
          <mesh filename="package://franka_gazebo/meshes/collision/hand.stl"/>
        </geometry>
      </collision>
    </link>

    <link name="${ns}_leftfinger">
      <inertial>
        <mass value="0.1" />
        <origin xyz="0 0.0145644 0.0227941" rpy="0 0 0" />
        <inertia ixx="3.01220925051e-05" ixy="0.0" ixz="0.0" iyy="2.95873808038e-05" iyz="0.0" izz="6.95125211657e-06" />
      </inertial>
      <visual>
        <origin xyz="${xyz}" rpy="0 0 0"/>
        <geometry>
          <mesh filename="package://franka_gazebo/meshes/visual/finger.dae"/>
        </geometry>
        <material name="">
          <color rgba="1 1 1 1"/>
        </material>
      </visual>
      <collision>
        <origin xyz="${xyz}" rpy="0 0 0"/>
        <geometry>
          <mesh filename="package://franka_gazebo/meshes/collision/finger.stl"/>
        </geometry>
      </collision>
    </link>

    <link name="${ns}_rightfinger">
      <inertial>
        <mass value="0.1" />
        <origin xyz="0 0.0145644 0.0227941" rpy="0 0 ${pi}" />
        <inertia ixx="3.01220925051e-05" ixy="0.0" ixz="0.0" iyy="2.95873808038e-05" iyz="0.0" izz="6.95125211657e-06" />
      </inertial>
      <visual>
        <origin xyz="0 0 0" rpy="0 0 ${pi}"/>
        <geometry>
          <mesh filename="package://franka_gazebo/meshes/visual/finger.dae"/>
        </geometry>
        <material name="">
          <color rgba="1 1 1 1"/>
        </material>
      </visual>
      <collision>
        <origin xyz="0 0 0" rpy="0 0 ${pi}"/>
        <geometry>
          <mesh filename="package://franka_gazebo/meshes/collision/finger.stl"/>
        </geometry>
      </collision>
    </link>

    <gazebo reference="${ns}_rightfinger">
      <mu1>100</mu1>
        <mu2>100</mu2>
        <kp>100000</kp>
        <fdir1>0 0 1</fdir1>
        <collision name="${ns}_rightfinger_collision">
      <surface>
        <friction>
          <torsional>
            <coefficient>100</coefficient>
            <use_patch_radius>true</use_patch_radius>
            <patch_radius>0.1</patch_radius>
            <surface_radius>0.1</surface_radius>

          </torsional>
        </friction>
      </surface>
      </collision>

    </gazebo>
    <gazebo reference="${ns}_leftfinger">
      <mu1>100</mu1>
        <mu2>100</mu2>
        <kp>100000</kp>
        <fdir1>0 0 1</fdir1>
        <collision name="${ns}__leftfinger_collision">
      <surface>
        <friction>
          <torsional>
            <coefficient>100</coefficient>
            <use_patch_radius>true</use_patch_radius>
            <patch_radius>0.1</patch_radius>
            <surface_radius>0.1</surface_radius>

          </torsional>
        </friction>
      </surface>
      </collision>
    </gazebo>

    <joint name="${ns}_finger_joint1" type="prismatic">
      <parent link="${ns}_hand"/>
      <child link="${ns}_leftfinger"/>
      <origin xyz="0 0 0.0584" rpy="0 0 0"/>
      <axis xyz="0 1 0"/>
      <limit effort="50" lower="-0.001" upper="0.06" velocity="0.1"/>
    </joint>
    <!-- Changed upper limit from 0.04 to 0.06 -->
    <joint name="${ns}_finger_joint2" type="prismatic">
      <parent link="${ns}_hand"/>
      <child link="${ns}_rightfinger"/>
      <origin xyz="0 0 0.0584" rpy="0 0 0"/>
      <axis xyz="0 -1 0"/>
      <limit effort="50" lower="-0.001" upper="0.06" velocity="0.1"/>
    </joint>

  </xacro:macro>
</robot>
